<robot name="test_robot">
  <link name="base_link" />
  <link name="intermediate_link"/>
  <link name="rod_link">
  <visual>
      <origin rpy="0 0 0" xyz="0 0 0.8"/>
      <geometry>
        <cylinder length="0.8" radius="0.05"/>
      </geometry>
       <material name="red">
        <color rgba="1 0 0 1"/>
      </material>
  </visual>
  <collision>
      <geometry>
        <cylinder length="0.8" radius="0.05"/>
      </geometry>
      <origin rpy="0 0 0" xyz="0 0 0.8"/>
    </collision>
    <inertial>
      <origin rpy="0 0 0" xyz="0 0 0.8"/>
       <mass value=".5"/>
       <inertia ixx="1" ixy="0" ixz="0" iyy="1" iyz="0" izz="1"/>
    </inertial>
   </link>



<joint name="joint_1" type="revolute">
    <axis xyz="0 1 0"/>
    <limit effort="10000" lower="-3.14" upper="3.14" velocity="5"/>
    <dynamics damping="0" friction="0"/>
    <origin rpy="0 0 0" xyz="0 0 0"/>
    <parent link="base_link"/>
    <child link="intermediate_link"/>
  </joint>

<joint name="joint_2" type="revolute">
    <axis xyz="1 0 0"/>
    <limit effort="10000" lower="-3.14" upper="3.14" velocity="5"/>
    <dynamics damping="0" friction="0"/>
    <origin rpy="0 0 0" xyz="0 0 0"/>
    <parent link="intermediate_link"/>
    <child link="rod_link"/>
  </joint>

</robot>
